[2025-05-05T23:53:53.543+0000] {local_task_job_runner.py:123} INFO - ::group::Pre task execution logs
[2025-05-05T23:53:53.575+0000] {taskinstance.py:2612} INFO - Dependencies all met for dep_context=non-requeueable deps ti=<TaskInstance: dbt_sequential_run.dbt_deps manual__2025-05-05T23:53:52.064784+00:00 [queued]>
[2025-05-05T23:53:53.589+0000] {taskinstance.py:2612} INFO - Dependencies all met for dep_context=requeueable deps ti=<TaskInstance: dbt_sequential_run.dbt_deps manual__2025-05-05T23:53:52.064784+00:00 [queued]>
[2025-05-05T23:53:53.591+0000] {taskinstance.py:2865} INFO - Starting attempt 1 of 2
[2025-05-05T23:53:53.613+0000] {taskinstance.py:2888} INFO - Executing <Task(BashOperator): dbt_deps> on 2025-05-05 23:53:52.064784+00:00
[2025-05-05T23:53:53.625+0000] {standard_task_runner.py:104} INFO - Running: ['***', 'tasks', 'run', 'dbt_sequential_run', 'dbt_deps', 'manual__2025-05-05T23:53:52.064784+00:00', '--job-id', '36', '--raw', '--subdir', 'DAGS_FOLDER/dbt_run_dag.py', '--cfg-path', '/tmp/tmp7aldt068']
[2025-05-05T23:53:53.631+0000] {standard_task_runner.py:105} INFO - Job 36: Subtask dbt_deps
[2025-05-05T23:53:53.631+0000] {logging_mixin.py:190} WARNING - /home/***/.local/lib/python3.12/site-packages/***/task/task_runner/standard_task_runner.py:70 DeprecationWarning: This process (pid=1600) is multi-threaded, use of fork() may lead to deadlocks in the child.
[2025-05-05T23:53:53.633+0000] {standard_task_runner.py:72} INFO - Started process 1603 to run task
[2025-05-05T23:53:53.711+0000] {task_command.py:467} INFO - Running <TaskInstance: dbt_sequential_run.dbt_deps manual__2025-05-05T23:53:52.064784+00:00 [running]> on host 5f6a5c55bc08
[2025-05-05T23:53:53.838+0000] {taskinstance.py:3131} INFO - Exporting env vars: AIRFLOW_CTX_DAG_OWNER='***' AIRFLOW_CTX_DAG_ID='dbt_sequential_run' AIRFLOW_CTX_TASK_ID='dbt_deps' AIRFLOW_CTX_EXECUTION_DATE='2025-05-05T23:53:52.064784+00:00' AIRFLOW_CTX_TRY_NUMBER='1' AIRFLOW_CTX_DAG_RUN_ID='manual__2025-05-05T23:53:52.064784+00:00'
[2025-05-05T23:53:53.840+0000] {taskinstance.py:731} INFO - ::endgroup::
[2025-05-05T23:53:53.866+0000] {subprocess.py:63} INFO - Tmp dir root location: /tmp
[2025-05-05T23:53:53.868+0000] {subprocess.py:75} INFO - Running command: ['/usr/bin/bash', '-c', '/home/***/.local/bin/dbt deps --profiles-dir /opt/***/dbt --project-dir /opt/***/dbt']
[2025-05-05T23:53:53.878+0000] {subprocess.py:86} INFO - Output:
[2025-05-05T23:53:58.137+0000] {subprocess.py:93} INFO - [0m23:53:58  Running with dbt=1.8.7
[2025-05-05T23:53:58.322+0000] {subprocess.py:93} INFO - [0m23:53:58  Warning: No packages were found in packages.yml
[2025-05-05T23:53:58.330+0000] {subprocess.py:93} INFO - [0m23:53:58  Encountered an error:
[2025-05-05T23:53:58.331+0000] {subprocess.py:93} INFO - [Errno 2] No such file or directory: 'dbt_packages'
[2025-05-05T23:53:58.334+0000] {subprocess.py:93} INFO - [0m23:53:58  Traceback (most recent call last):
[2025-05-05T23:53:58.335+0000] {subprocess.py:93} INFO -   File "/home/***/.local/lib/python3.12/site-packages/dbt/cli/requires.py", line 138, in wrapper
[2025-05-05T23:53:58.336+0000] {subprocess.py:93} INFO -     result, success = func(*args, **kwargs)
[2025-05-05T23:53:58.337+0000] {subprocess.py:93} INFO -                       ^^^^^^^^^^^^^^^^^^^^^
[2025-05-05T23:53:58.338+0000] {subprocess.py:93} INFO -   File "/home/***/.local/lib/python3.12/site-packages/dbt/cli/requires.py", line 101, in wrapper
[2025-05-05T23:53:58.339+0000] {subprocess.py:93} INFO -     return func(*args, **kwargs)
[2025-05-05T23:53:58.339+0000] {subprocess.py:93} INFO -            ^^^^^^^^^^^^^^^^^^^^^
[2025-05-05T23:53:58.340+0000] {subprocess.py:93} INFO -   File "/home/***/.local/lib/python3.12/site-packages/dbt/cli/requires.py", line 201, in wrapper
[2025-05-05T23:53:58.341+0000] {subprocess.py:93} INFO -     return func(*args, **kwargs)
[2025-05-05T23:53:58.342+0000] {subprocess.py:93} INFO -            ^^^^^^^^^^^^^^^^^^^^^
[2025-05-05T23:53:58.343+0000] {subprocess.py:93} INFO -   File "/home/***/.local/lib/python3.12/site-packages/dbt/cli/requires.py", line 247, in wrapper
[2025-05-05T23:53:58.344+0000] {subprocess.py:93} INFO -     return func(*args, **kwargs)
[2025-05-05T23:53:58.345+0000] {subprocess.py:93} INFO -            ^^^^^^^^^^^^^^^^^^^^^
[2025-05-05T23:53:58.346+0000] {subprocess.py:93} INFO -   File "/home/***/.local/lib/python3.12/site-packages/dbt/cli/main.py", line 447, in deps
[2025-05-05T23:53:58.347+0000] {subprocess.py:93} INFO -     results = task.run()
[2025-05-05T23:53:58.347+0000] {subprocess.py:93} INFO -               ^^^^^^^^^^
[2025-05-05T23:53:58.348+0000] {subprocess.py:93} INFO -   File "/home/***/.local/lib/python3.12/site-packages/dbt/task/deps.py", line 233, in run
[2025-05-05T23:53:58.349+0000] {subprocess.py:93} INFO -     system.rmtree(self.project.packages_install_path)
[2025-05-05T23:53:58.350+0000] {subprocess.py:93} INFO -   File "/home/***/.local/lib/python3.12/site-packages/dbt_common/clients/system.py", line 715, in rmtree
[2025-05-05T23:53:58.351+0000] {subprocess.py:93} INFO -     return shutil.rmtree(path, onerror=chmod_and_retry)
[2025-05-05T23:53:58.352+0000] {subprocess.py:93} INFO -            ^^^^^^^^^^^^^^^^^^^^^^^^^^^^^^^^^^^^^^^^^^^^
[2025-05-05T23:53:58.353+0000] {subprocess.py:93} INFO -   File "/usr/local/lib/python3.12/shutil.py", line 759, in rmtree
[2025-05-05T23:53:58.354+0000] {subprocess.py:93} INFO -     _rmtree_safe_fd(stack, onexc)
[2025-05-05T23:53:58.355+0000] {subprocess.py:93} INFO -   File "/usr/local/lib/python3.12/shutil.py", line 703, in _rmtree_safe_fd
[2025-05-05T23:53:58.356+0000] {subprocess.py:93} INFO -     onexc(func, path, err)
[2025-05-05T23:53:58.356+0000] {subprocess.py:93} INFO -   File "/usr/local/lib/python3.12/shutil.py", line 750, in onexc
[2025-05-05T23:53:58.357+0000] {subprocess.py:93} INFO -     return onerror(func, path, exc_info)
[2025-05-05T23:53:58.358+0000] {subprocess.py:93} INFO -            ^^^^^^^^^^^^^^^^^^^^^^^^^^^^^
[2025-05-05T23:53:58.359+0000] {subprocess.py:93} INFO -   File "/usr/local/lib/python3.12/shutil.py", line 662, in _rmtree_safe_fd
[2025-05-05T23:53:58.360+0000] {subprocess.py:93} INFO -     os.rmdir(name, dir_fd=dirfd)
[2025-05-05T23:53:58.361+0000] {subprocess.py:93} INFO - FileNotFoundError: [Errno 2] No such file or directory: 'dbt_packages'
[2025-05-05T23:53:58.361+0000] {subprocess.py:93} INFO - 
[2025-05-05T23:53:58.983+0000] {subprocess.py:97} INFO - Command exited with return code 2
[2025-05-05T23:53:59.002+0000] {taskinstance.py:3310} ERROR - Task failed with exception
Traceback (most recent call last):
  File "/home/airflow/.local/lib/python3.12/site-packages/airflow/models/taskinstance.py", line 767, in _execute_task
    result = _execute_callable(context=context, **execute_callable_kwargs)
             ^^^^^^^^^^^^^^^^^^^^^^^^^^^^^^^^^^^^^^^^^^^^^^^^^^^^^^^^^^^^^
  File "/home/airflow/.local/lib/python3.12/site-packages/airflow/models/taskinstance.py", line 733, in _execute_callable
    return ExecutionCallableRunner(
           ^^^^^^^^^^^^^^^^^^^^^^^^
  File "/home/airflow/.local/lib/python3.12/site-packages/airflow/utils/operator_helpers.py", line 252, in run
    return self.func(*args, **kwargs)
           ^^^^^^^^^^^^^^^^^^^^^^^^^^
  File "/home/airflow/.local/lib/python3.12/site-packages/airflow/models/baseoperator.py", line 406, in wrapper
    return func(self, *args, **kwargs)
           ^^^^^^^^^^^^^^^^^^^^^^^^^^^
  File "/home/airflow/.local/lib/python3.12/site-packages/airflow/operators/bash.py", line 249, in execute
    raise AirflowException(
airflow.exceptions.AirflowException: Bash command failed. The command returned a non-zero exit code 2.
[2025-05-05T23:53:59.012+0000] {taskinstance.py:1225} INFO - Marking task as UP_FOR_RETRY. dag_id=dbt_sequential_run, task_id=dbt_deps, run_id=manual__2025-05-05T23:53:52.064784+00:00, execution_date=20250505T235352, start_date=20250505T235353, end_date=20250505T235359
[2025-05-05T23:53:59.031+0000] {taskinstance.py:340} INFO - ::group::Post task execution logs
[2025-05-05T23:53:59.032+0000] {standard_task_runner.py:124} ERROR - Failed to execute job 36 for task dbt_deps (Bash command failed. The command returned a non-zero exit code 2.; 1603)
Traceback (most recent call last):
  File "/home/airflow/.local/lib/python3.12/site-packages/airflow/task/task_runner/standard_task_runner.py", line 117, in _start_by_fork
    ret = args.func(args, dag=self.dag)
          ^^^^^^^^^^^^^^^^^^^^^^^^^^^^^
  File "/home/airflow/.local/lib/python3.12/site-packages/airflow/cli/cli_config.py", line 49, in command
    return func(*args, **kwargs)
           ^^^^^^^^^^^^^^^^^^^^^
  File "/home/airflow/.local/lib/python3.12/site-packages/airflow/utils/cli.py", line 115, in wrapper
    return f(*args, **kwargs)
           ^^^^^^^^^^^^^^^^^^
  File "/home/airflow/.local/lib/python3.12/site-packages/airflow/cli/commands/task_command.py", line 483, in task_run
    task_return_code = _run_task_by_selected_method(args, _dag, ti)
                       ^^^^^^^^^^^^^^^^^^^^^^^^^^^^^^^^^^^^^^^^^^^^
  File "/home/airflow/.local/lib/python3.12/site-packages/airflow/cli/commands/task_command.py", line 256, in _run_task_by_selected_method
    return _run_raw_task(args, ti)
           ^^^^^^^^^^^^^^^^^^^^^^^
  File "/home/airflow/.local/lib/python3.12/site-packages/airflow/cli/commands/task_command.py", line 341, in _run_raw_task
    return ti._run_raw_task(
           ^^^^^^^^^^^^^^^^^
  File "/home/airflow/.local/lib/python3.12/site-packages/airflow/utils/session.py", line 97, in wrapper
    return func(*args, session=session, **kwargs)
           ^^^^^^^^^^^^^^^^^^^^^^^^^^^^^^^^^^^^^^
  File "/home/airflow/.local/lib/python3.12/site-packages/airflow/models/taskinstance.py", line 3004, in _run_raw_task
    return _run_raw_task(
           ^^^^^^^^^^^^^^
  File "/home/airflow/.local/lib/python3.12/site-packages/airflow/models/taskinstance.py", line 273, in _run_raw_task
    TaskInstance._execute_task_with_callbacks(
  File "/home/airflow/.local/lib/python3.12/site-packages/airflow/models/taskinstance.py", line 3158, in _execute_task_with_callbacks
    result = self._execute_task(context, task_orig)
             ^^^^^^^^^^^^^^^^^^^^^^^^^^^^^^^^^^^^^^
  File "/home/airflow/.local/lib/python3.12/site-packages/airflow/models/taskinstance.py", line 3182, in _execute_task
    return _execute_task(self, context, task_orig)
           ^^^^^^^^^^^^^^^^^^^^^^^^^^^^^^^^^^^^^^^
  File "/home/airflow/.local/lib/python3.12/site-packages/airflow/models/taskinstance.py", line 767, in _execute_task
    result = _execute_callable(context=context, **execute_callable_kwargs)
             ^^^^^^^^^^^^^^^^^^^^^^^^^^^^^^^^^^^^^^^^^^^^^^^^^^^^^^^^^^^^^
  File "/home/airflow/.local/lib/python3.12/site-packages/airflow/models/taskinstance.py", line 733, in _execute_callable
    return ExecutionCallableRunner(
           ^^^^^^^^^^^^^^^^^^^^^^^^
  File "/home/airflow/.local/lib/python3.12/site-packages/airflow/utils/operator_helpers.py", line 252, in run
    return self.func(*args, **kwargs)
           ^^^^^^^^^^^^^^^^^^^^^^^^^^
  File "/home/airflow/.local/lib/python3.12/site-packages/airflow/models/baseoperator.py", line 406, in wrapper
    return func(self, *args, **kwargs)
           ^^^^^^^^^^^^^^^^^^^^^^^^^^^
  File "/home/airflow/.local/lib/python3.12/site-packages/airflow/operators/bash.py", line 249, in execute
    raise AirflowException(
airflow.exceptions.AirflowException: Bash command failed. The command returned a non-zero exit code 2.
[2025-05-05T23:53:59.041+0000] {local_task_job_runner.py:266} INFO - Task exited with return code 1
[2025-05-05T23:53:59.071+0000] {taskinstance.py:3900} INFO - 0 downstream tasks scheduled from follow-on schedule check
[2025-05-05T23:53:59.074+0000] {local_task_job_runner.py:245} INFO - ::endgroup::
