[2025-05-05T23:44:21.305+0000] {local_task_job_runner.py:123} INFO - ::group::Pre task execution logs
[2025-05-05T23:44:21.324+0000] {taskinstance.py:2612} INFO - Dependencies all met for dep_context=non-requeueable deps ti=<TaskInstance: dbt_sequential_run.dbt_run_marts manual__2025-05-05T23:43:53.150272+00:00 [queued]>
[2025-05-05T23:44:21.333+0000] {taskinstance.py:2612} INFO - Dependencies all met for dep_context=requeueable deps ti=<TaskInstance: dbt_sequential_run.dbt_run_marts manual__2025-05-05T23:43:53.150272+00:00 [queued]>
[2025-05-05T23:44:21.334+0000] {taskinstance.py:2865} INFO - Starting attempt 1 of 2
[2025-05-05T23:44:21.348+0000] {taskinstance.py:2888} INFO - Executing <Task(BashOperator): dbt_run_marts> on 2025-05-05 23:43:53.150272+00:00
[2025-05-05T23:44:21.356+0000] {standard_task_runner.py:104} INFO - Running: ['***', 'tasks', 'run', 'dbt_sequential_run', 'dbt_run_marts', 'manual__2025-05-05T23:43:53.150272+00:00', '--job-id', '20', '--raw', '--subdir', 'DAGS_FOLDER/dbt_run_dag.py', '--cfg-path', '/tmp/tmpyhp167w1']
[2025-05-05T23:44:21.359+0000] {logging_mixin.py:190} WARNING - /home/***/.local/lib/python3.12/site-packages/***/task/task_runner/standard_task_runner.py:70 DeprecationWarning: This process (pid=759) is multi-threaded, use of fork() may lead to deadlocks in the child.
[2025-05-05T23:44:21.360+0000] {standard_task_runner.py:105} INFO - Job 20: Subtask dbt_run_marts
[2025-05-05T23:44:21.362+0000] {standard_task_runner.py:72} INFO - Started process 760 to run task
[2025-05-05T23:44:21.414+0000] {task_command.py:467} INFO - Running <TaskInstance: dbt_sequential_run.dbt_run_marts manual__2025-05-05T23:43:53.150272+00:00 [running]> on host 5f6a5c55bc08
[2025-05-05T23:44:21.490+0000] {taskinstance.py:3131} INFO - Exporting env vars: AIRFLOW_CTX_DAG_OWNER='***' AIRFLOW_CTX_DAG_ID='dbt_sequential_run' AIRFLOW_CTX_TASK_ID='dbt_run_marts' AIRFLOW_CTX_EXECUTION_DATE='2025-05-05T23:43:53.150272+00:00' AIRFLOW_CTX_TRY_NUMBER='1' AIRFLOW_CTX_DAG_RUN_ID='manual__2025-05-05T23:43:53.150272+00:00'
[2025-05-05T23:44:21.497+0000] {taskinstance.py:731} INFO - ::endgroup::
[2025-05-05T23:44:21.515+0000] {subprocess.py:63} INFO - Tmp dir root location: /tmp
[2025-05-05T23:44:21.518+0000] {subprocess.py:75} INFO - Running command: ['/usr/bin/bash', '-c', '/home/***/.local/bin/dbt run --profiles-dir /opt/***/dbt --project-dir /opt/***/dbt --select marts']
[2025-05-05T23:44:21.526+0000] {subprocess.py:86} INFO - Output:
[2025-05-05T23:44:23.785+0000] {subprocess.py:93} INFO - [0m23:44:23  Running with dbt=1.8.7
[2025-05-05T23:44:25.052+0000] {subprocess.py:93} INFO - [0m23:44:25  Registered adapter: snowflake=1.8.1
[2025-05-05T23:44:26.424+0000] {subprocess.py:93} INFO - [0m23:44:26  Found 12 models, 10 data tests, 7 sources, 459 macros
[2025-05-05T23:44:26.430+0000] {subprocess.py:93} INFO - [0m23:44:26
[2025-05-05T23:44:28.322+0000] {subprocess.py:93} INFO - [0m23:44:28  Concurrency: 4 threads (target='dev')
[2025-05-05T23:44:28.328+0000] {subprocess.py:93} INFO - [0m23:44:28
[2025-05-05T23:44:28.343+0000] {subprocess.py:93} INFO - [0m23:44:28  1 of 5 START sql table model RAW_public.dim_address ............................ [RUN]
[2025-05-05T23:44:28.345+0000] {subprocess.py:93} INFO - [0m23:44:28  2 of 5 START sql table model RAW_public.dim_customer ........................... [RUN]
[2025-05-05T23:44:28.348+0000] {subprocess.py:93} INFO - [0m23:44:28  3 of 5 START sql incremental model RAW_public.fact_churn ....................... [RUN]
[2025-05-05T23:44:30.925+0000] {subprocess.py:93} INFO - [0m23:44:30  3 of 5 OK created sql incremental model RAW_public.fact_churn .................. [[32mSUCCESS 0[0m in 2.56s]
[2025-05-05T23:44:30.949+0000] {subprocess.py:93} INFO - [0m23:44:30  4 of 5 START sql table model RAW_public.churn_metrics .......................... [RUN]
[2025-05-05T23:44:32.809+0000] {subprocess.py:93} INFO - [0m23:44:32  4 of 5 ERROR creating sql table model RAW_public.churn_metrics ................. [[31mERROR[0m in 1.86s]
[2025-05-05T23:44:33.812+0000] {subprocess.py:93} INFO - [0m23:44:33  1 of 5 OK created sql table model RAW_public.dim_address ....................... [[32mSUCCESS 1[0m in 5.46s]
[2025-05-05T23:44:33.815+0000] {subprocess.py:93} INFO - [0m23:44:33  5 of 5 START sql table model RAW_public.churn_map .............................. [RUN]
[2025-05-05T23:44:33.823+0000] {subprocess.py:93} INFO - [0m23:44:33  2 of 5 OK created sql table model RAW_public.dim_customer ...................... [[32mSUCCESS 1[0m in 5.46s]
[2025-05-05T23:44:35.821+0000] {subprocess.py:93} INFO - [0m23:44:35  5 of 5 OK created sql table model RAW_public.churn_map ......................... [[32mSUCCESS 1[0m in 2.00s]
[2025-05-05T23:44:35.838+0000] {subprocess.py:93} INFO - [0m23:44:35
[2025-05-05T23:44:35.842+0000] {subprocess.py:93} INFO - [0m23:44:35  Finished running 1 incremental model, 4 table models in 0 hours 0 minutes and 9.41 seconds (9.41s).
[2025-05-05T23:44:36.062+0000] {subprocess.py:93} INFO - [0m23:44:36
[2025-05-05T23:44:36.063+0000] {subprocess.py:93} INFO - [0m23:44:36  [31mCompleted with 1 error and 0 warnings:[0m
[2025-05-05T23:44:36.064+0000] {subprocess.py:93} INFO - [0m23:44:36
[2025-05-05T23:44:36.065+0000] {subprocess.py:93} INFO - [0m23:44:36    Database Error in model churn_metrics (models/marts/churn_metrics.sql)
[2025-05-05T23:44:36.066+0000] {subprocess.py:93} INFO -   002003 (42S02): SQL compilation error:
[2025-05-05T23:44:36.067+0000] {subprocess.py:93} INFO -   Object 'MONTHLY' does not exist or not authorized.
[2025-05-05T23:44:36.068+0000] {subprocess.py:93} INFO -   compiled code at target/run/customer_churn/models/marts/churn_metrics.sql
[2025-05-05T23:44:36.068+0000] {subprocess.py:93} INFO - [0m23:44:36
[2025-05-05T23:44:36.069+0000] {subprocess.py:93} INFO - [0m23:44:36  Done. PASS=4 WARN=0 ERROR=1 SKIP=0 TOTAL=5
[2025-05-05T23:44:36.824+0000] {subprocess.py:97} INFO - Command exited with return code 1
[2025-05-05T23:44:36.836+0000] {taskinstance.py:3310} ERROR - Task failed with exception
Traceback (most recent call last):
  File "/home/airflow/.local/lib/python3.12/site-packages/airflow/models/taskinstance.py", line 767, in _execute_task
    result = _execute_callable(context=context, **execute_callable_kwargs)
             ^^^^^^^^^^^^^^^^^^^^^^^^^^^^^^^^^^^^^^^^^^^^^^^^^^^^^^^^^^^^^
  File "/home/airflow/.local/lib/python3.12/site-packages/airflow/models/taskinstance.py", line 733, in _execute_callable
    return ExecutionCallableRunner(
           ^^^^^^^^^^^^^^^^^^^^^^^^
  File "/home/airflow/.local/lib/python3.12/site-packages/airflow/utils/operator_helpers.py", line 252, in run
    return self.func(*args, **kwargs)
           ^^^^^^^^^^^^^^^^^^^^^^^^^^
  File "/home/airflow/.local/lib/python3.12/site-packages/airflow/models/baseoperator.py", line 406, in wrapper
    return func(self, *args, **kwargs)
           ^^^^^^^^^^^^^^^^^^^^^^^^^^^
  File "/home/airflow/.local/lib/python3.12/site-packages/airflow/operators/bash.py", line 249, in execute
    raise AirflowException(
airflow.exceptions.AirflowException: Bash command failed. The command returned a non-zero exit code 1.
[2025-05-05T23:44:36.845+0000] {taskinstance.py:1225} INFO - Marking task as UP_FOR_RETRY. dag_id=dbt_sequential_run, task_id=dbt_run_marts, run_id=manual__2025-05-05T23:43:53.150272+00:00, execution_date=20250505T234353, start_date=20250505T234421, end_date=20250505T234436
[2025-05-05T23:44:36.862+0000] {taskinstance.py:340} INFO - ::group::Post task execution logs
[2025-05-05T23:44:36.864+0000] {standard_task_runner.py:124} ERROR - Failed to execute job 20 for task dbt_run_marts (Bash command failed. The command returned a non-zero exit code 1.; 760)
Traceback (most recent call last):
  File "/home/airflow/.local/lib/python3.12/site-packages/airflow/task/task_runner/standard_task_runner.py", line 117, in _start_by_fork
    ret = args.func(args, dag=self.dag)
          ^^^^^^^^^^^^^^^^^^^^^^^^^^^^^
  File "/home/airflow/.local/lib/python3.12/site-packages/airflow/cli/cli_config.py", line 49, in command
    return func(*args, **kwargs)
           ^^^^^^^^^^^^^^^^^^^^^
  File "/home/airflow/.local/lib/python3.12/site-packages/airflow/utils/cli.py", line 115, in wrapper
    return f(*args, **kwargs)
           ^^^^^^^^^^^^^^^^^^
  File "/home/airflow/.local/lib/python3.12/site-packages/airflow/cli/commands/task_command.py", line 483, in task_run
    task_return_code = _run_task_by_selected_method(args, _dag, ti)
                       ^^^^^^^^^^^^^^^^^^^^^^^^^^^^^^^^^^^^^^^^^^^^
  File "/home/airflow/.local/lib/python3.12/site-packages/airflow/cli/commands/task_command.py", line 256, in _run_task_by_selected_method
    return _run_raw_task(args, ti)
           ^^^^^^^^^^^^^^^^^^^^^^^
  File "/home/airflow/.local/lib/python3.12/site-packages/airflow/cli/commands/task_command.py", line 341, in _run_raw_task
    return ti._run_raw_task(
           ^^^^^^^^^^^^^^^^^
  File "/home/airflow/.local/lib/python3.12/site-packages/airflow/utils/session.py", line 97, in wrapper
    return func(*args, session=session, **kwargs)
           ^^^^^^^^^^^^^^^^^^^^^^^^^^^^^^^^^^^^^^
  File "/home/airflow/.local/lib/python3.12/site-packages/airflow/models/taskinstance.py", line 3004, in _run_raw_task
    return _run_raw_task(
           ^^^^^^^^^^^^^^
  File "/home/airflow/.local/lib/python3.12/site-packages/airflow/models/taskinstance.py", line 273, in _run_raw_task
    TaskInstance._execute_task_with_callbacks(
  File "/home/airflow/.local/lib/python3.12/site-packages/airflow/models/taskinstance.py", line 3158, in _execute_task_with_callbacks
    result = self._execute_task(context, task_orig)
             ^^^^^^^^^^^^^^^^^^^^^^^^^^^^^^^^^^^^^^
  File "/home/airflow/.local/lib/python3.12/site-packages/airflow/models/taskinstance.py", line 3182, in _execute_task
    return _execute_task(self, context, task_orig)
           ^^^^^^^^^^^^^^^^^^^^^^^^^^^^^^^^^^^^^^^
  File "/home/airflow/.local/lib/python3.12/site-packages/airflow/models/taskinstance.py", line 767, in _execute_task
    result = _execute_callable(context=context, **execute_callable_kwargs)
             ^^^^^^^^^^^^^^^^^^^^^^^^^^^^^^^^^^^^^^^^^^^^^^^^^^^^^^^^^^^^^
  File "/home/airflow/.local/lib/python3.12/site-packages/airflow/models/taskinstance.py", line 733, in _execute_callable
    return ExecutionCallableRunner(
           ^^^^^^^^^^^^^^^^^^^^^^^^
  File "/home/airflow/.local/lib/python3.12/site-packages/airflow/utils/operator_helpers.py", line 252, in run
    return self.func(*args, **kwargs)
           ^^^^^^^^^^^^^^^^^^^^^^^^^^
  File "/home/airflow/.local/lib/python3.12/site-packages/airflow/models/baseoperator.py", line 406, in wrapper
    return func(self, *args, **kwargs)
           ^^^^^^^^^^^^^^^^^^^^^^^^^^^
  File "/home/airflow/.local/lib/python3.12/site-packages/airflow/operators/bash.py", line 249, in execute
    raise AirflowException(
airflow.exceptions.AirflowException: Bash command failed. The command returned a non-zero exit code 1.
[2025-05-05T23:44:36.911+0000] {local_task_job_runner.py:266} INFO - Task exited with return code 1
[2025-05-05T23:44:36.937+0000] {taskinstance.py:3900} INFO - 0 downstream tasks scheduled from follow-on schedule check
[2025-05-05T23:44:36.941+0000] {local_task_job_runner.py:245} INFO - ::endgroup::
