[2025-05-05T23:39:37.079+0000] {local_task_job_runner.py:123} INFO - ::group::Pre task execution logs
[2025-05-05T23:39:37.106+0000] {taskinstance.py:2612} INFO - Dependencies all met for dep_context=non-requeueable deps ti=<TaskInstance: dbt_sequential_run.dbt_deps manual__2025-05-05T23:39:36.223369+00:00 [queued]>
[2025-05-05T23:39:37.119+0000] {taskinstance.py:2612} INFO - Dependencies all met for dep_context=requeueable deps ti=<TaskInstance: dbt_sequential_run.dbt_deps manual__2025-05-05T23:39:36.223369+00:00 [queued]>
[2025-05-05T23:39:37.120+0000] {taskinstance.py:2865} INFO - Starting attempt 1 of 2
[2025-05-05T23:39:37.141+0000] {taskinstance.py:2888} INFO - Executing <Task(BashOperator): dbt_deps> on 2025-05-05 23:39:36.223369+00:00
[2025-05-05T23:39:37.152+0000] {standard_task_runner.py:104} INFO - Running: ['***', 'tasks', 'run', 'dbt_sequential_run', 'dbt_deps', 'manual__2025-05-05T23:39:36.223369+00:00', '--job-id', '13', '--raw', '--subdir', 'DAGS_FOLDER/dbt_run_dag.py', '--cfg-path', '/tmp/tmp7h_d8gw4']
[2025-05-05T23:39:37.159+0000] {logging_mixin.py:190} WARNING - /home/***/.local/lib/python3.12/site-packages/***/task/task_runner/standard_task_runner.py:70 DeprecationWarning: This process (pid=374) is multi-threaded, use of fork() may lead to deadlocks in the child.
[2025-05-05T23:39:37.160+0000] {standard_task_runner.py:105} INFO - Job 13: Subtask dbt_deps
[2025-05-05T23:39:37.161+0000] {standard_task_runner.py:72} INFO - Started process 375 to run task
[2025-05-05T23:39:37.245+0000] {task_command.py:467} INFO - Running <TaskInstance: dbt_sequential_run.dbt_deps manual__2025-05-05T23:39:36.223369+00:00 [running]> on host 5f6a5c55bc08
[2025-05-05T23:39:37.374+0000] {taskinstance.py:3131} INFO - Exporting env vars: AIRFLOW_CTX_DAG_OWNER='***' AIRFLOW_CTX_DAG_ID='dbt_sequential_run' AIRFLOW_CTX_TASK_ID='dbt_deps' AIRFLOW_CTX_EXECUTION_DATE='2025-05-05T23:39:36.223369+00:00' AIRFLOW_CTX_TRY_NUMBER='1' AIRFLOW_CTX_DAG_RUN_ID='manual__2025-05-05T23:39:36.223369+00:00'
[2025-05-05T23:39:37.376+0000] {taskinstance.py:731} INFO - ::endgroup::
[2025-05-05T23:39:37.403+0000] {subprocess.py:63} INFO - Tmp dir root location: /tmp
[2025-05-05T23:39:37.404+0000] {subprocess.py:75} INFO - Running command: ['/usr/bin/bash', '-c', '/home/***/.local/bin/dbt deps --profiles-dir /opt/***/dbt --project-dir /opt/***/dbt']
[2025-05-05T23:39:37.418+0000] {subprocess.py:86} INFO - Output:
[2025-05-05T23:39:39.964+0000] {subprocess.py:93} INFO - [0m23:39:39  Running with dbt=1.8.7
[2025-05-05T23:39:40.134+0000] {subprocess.py:93} INFO - [0m23:39:40  Warning: No packages were found in packages.yml
[2025-05-05T23:39:40.148+0000] {subprocess.py:93} INFO - [0m23:39:40  Encountered an error:
[2025-05-05T23:39:40.150+0000] {subprocess.py:93} INFO - [Errno 2] No such file or directory: 'dbt_packages'
[2025-05-05T23:39:40.153+0000] {subprocess.py:93} INFO - [0m23:39:40  Traceback (most recent call last):
[2025-05-05T23:39:40.154+0000] {subprocess.py:93} INFO -   File "/home/***/.local/lib/python3.12/site-packages/dbt/cli/requires.py", line 138, in wrapper
[2025-05-05T23:39:40.156+0000] {subprocess.py:93} INFO -     result, success = func(*args, **kwargs)
[2025-05-05T23:39:40.157+0000] {subprocess.py:93} INFO -                       ^^^^^^^^^^^^^^^^^^^^^
[2025-05-05T23:39:40.158+0000] {subprocess.py:93} INFO -   File "/home/***/.local/lib/python3.12/site-packages/dbt/cli/requires.py", line 101, in wrapper
[2025-05-05T23:39:40.159+0000] {subprocess.py:93} INFO -     return func(*args, **kwargs)
[2025-05-05T23:39:40.160+0000] {subprocess.py:93} INFO -            ^^^^^^^^^^^^^^^^^^^^^
[2025-05-05T23:39:40.161+0000] {subprocess.py:93} INFO -   File "/home/***/.local/lib/python3.12/site-packages/dbt/cli/requires.py", line 201, in wrapper
[2025-05-05T23:39:40.162+0000] {subprocess.py:93} INFO -     return func(*args, **kwargs)
[2025-05-05T23:39:40.162+0000] {subprocess.py:93} INFO -            ^^^^^^^^^^^^^^^^^^^^^
[2025-05-05T23:39:40.163+0000] {subprocess.py:93} INFO -   File "/home/***/.local/lib/python3.12/site-packages/dbt/cli/requires.py", line 247, in wrapper
[2025-05-05T23:39:40.164+0000] {subprocess.py:93} INFO -     return func(*args, **kwargs)
[2025-05-05T23:39:40.165+0000] {subprocess.py:93} INFO -            ^^^^^^^^^^^^^^^^^^^^^
[2025-05-05T23:39:40.166+0000] {subprocess.py:93} INFO -   File "/home/***/.local/lib/python3.12/site-packages/dbt/cli/main.py", line 447, in deps
[2025-05-05T23:39:40.167+0000] {subprocess.py:93} INFO -     results = task.run()
[2025-05-05T23:39:40.167+0000] {subprocess.py:93} INFO -               ^^^^^^^^^^
[2025-05-05T23:39:40.168+0000] {subprocess.py:93} INFO -   File "/home/***/.local/lib/python3.12/site-packages/dbt/task/deps.py", line 233, in run
[2025-05-05T23:39:40.169+0000] {subprocess.py:93} INFO -     system.rmtree(self.project.packages_install_path)
[2025-05-05T23:39:40.170+0000] {subprocess.py:93} INFO -   File "/home/***/.local/lib/python3.12/site-packages/dbt_common/clients/system.py", line 715, in rmtree
[2025-05-05T23:39:40.170+0000] {subprocess.py:93} INFO -     return shutil.rmtree(path, onerror=chmod_and_retry)
[2025-05-05T23:39:40.179+0000] {subprocess.py:93} INFO -            ^^^^^^^^^^^^^^^^^^^^^^^^^^^^^^^^^^^^^^^^^^^^
[2025-05-05T23:39:40.180+0000] {subprocess.py:93} INFO -   File "/usr/local/lib/python3.12/shutil.py", line 759, in rmtree
[2025-05-05T23:39:40.181+0000] {subprocess.py:93} INFO -     _rmtree_safe_fd(stack, onexc)
[2025-05-05T23:39:40.182+0000] {subprocess.py:93} INFO -   File "/usr/local/lib/python3.12/shutil.py", line 703, in _rmtree_safe_fd
[2025-05-05T23:39:40.182+0000] {subprocess.py:93} INFO -     onexc(func, path, err)
[2025-05-05T23:39:40.185+0000] {subprocess.py:93} INFO -   File "/usr/local/lib/python3.12/shutil.py", line 750, in onexc
[2025-05-05T23:39:40.187+0000] {subprocess.py:93} INFO -     return onerror(func, path, exc_info)
[2025-05-05T23:39:40.188+0000] {subprocess.py:93} INFO -            ^^^^^^^^^^^^^^^^^^^^^^^^^^^^^
[2025-05-05T23:39:40.190+0000] {subprocess.py:93} INFO -   File "/usr/local/lib/python3.12/shutil.py", line 662, in _rmtree_safe_fd
[2025-05-05T23:39:40.191+0000] {subprocess.py:93} INFO -     os.rmdir(name, dir_fd=dirfd)
[2025-05-05T23:39:40.193+0000] {subprocess.py:93} INFO - FileNotFoundError: [Errno 2] No such file or directory: 'dbt_packages'
[2025-05-05T23:39:40.194+0000] {subprocess.py:93} INFO - 
[2025-05-05T23:39:40.845+0000] {subprocess.py:97} INFO - Command exited with return code 2
[2025-05-05T23:39:40.874+0000] {taskinstance.py:3310} ERROR - Task failed with exception
Traceback (most recent call last):
  File "/home/airflow/.local/lib/python3.12/site-packages/airflow/models/taskinstance.py", line 767, in _execute_task
    result = _execute_callable(context=context, **execute_callable_kwargs)
             ^^^^^^^^^^^^^^^^^^^^^^^^^^^^^^^^^^^^^^^^^^^^^^^^^^^^^^^^^^^^^
  File "/home/airflow/.local/lib/python3.12/site-packages/airflow/models/taskinstance.py", line 733, in _execute_callable
    return ExecutionCallableRunner(
           ^^^^^^^^^^^^^^^^^^^^^^^^
  File "/home/airflow/.local/lib/python3.12/site-packages/airflow/utils/operator_helpers.py", line 252, in run
    return self.func(*args, **kwargs)
           ^^^^^^^^^^^^^^^^^^^^^^^^^^
  File "/home/airflow/.local/lib/python3.12/site-packages/airflow/models/baseoperator.py", line 406, in wrapper
    return func(self, *args, **kwargs)
           ^^^^^^^^^^^^^^^^^^^^^^^^^^^
  File "/home/airflow/.local/lib/python3.12/site-packages/airflow/operators/bash.py", line 249, in execute
    raise AirflowException(
airflow.exceptions.AirflowException: Bash command failed. The command returned a non-zero exit code 2.
[2025-05-05T23:39:40.883+0000] {taskinstance.py:1225} INFO - Marking task as UP_FOR_RETRY. dag_id=dbt_sequential_run, task_id=dbt_deps, run_id=manual__2025-05-05T23:39:36.223369+00:00, execution_date=20250505T233936, start_date=20250505T233937, end_date=20250505T233940
[2025-05-05T23:39:40.898+0000] {taskinstance.py:340} INFO - ::group::Post task execution logs
[2025-05-05T23:39:40.899+0000] {standard_task_runner.py:124} ERROR - Failed to execute job 13 for task dbt_deps (Bash command failed. The command returned a non-zero exit code 2.; 375)
Traceback (most recent call last):
  File "/home/airflow/.local/lib/python3.12/site-packages/airflow/task/task_runner/standard_task_runner.py", line 117, in _start_by_fork
    ret = args.func(args, dag=self.dag)
          ^^^^^^^^^^^^^^^^^^^^^^^^^^^^^
  File "/home/airflow/.local/lib/python3.12/site-packages/airflow/cli/cli_config.py", line 49, in command
    return func(*args, **kwargs)
           ^^^^^^^^^^^^^^^^^^^^^
  File "/home/airflow/.local/lib/python3.12/site-packages/airflow/utils/cli.py", line 115, in wrapper
    return f(*args, **kwargs)
           ^^^^^^^^^^^^^^^^^^
  File "/home/airflow/.local/lib/python3.12/site-packages/airflow/cli/commands/task_command.py", line 483, in task_run
    task_return_code = _run_task_by_selected_method(args, _dag, ti)
                       ^^^^^^^^^^^^^^^^^^^^^^^^^^^^^^^^^^^^^^^^^^^^
  File "/home/airflow/.local/lib/python3.12/site-packages/airflow/cli/commands/task_command.py", line 256, in _run_task_by_selected_method
    return _run_raw_task(args, ti)
           ^^^^^^^^^^^^^^^^^^^^^^^
  File "/home/airflow/.local/lib/python3.12/site-packages/airflow/cli/commands/task_command.py", line 341, in _run_raw_task
    return ti._run_raw_task(
           ^^^^^^^^^^^^^^^^^
  File "/home/airflow/.local/lib/python3.12/site-packages/airflow/utils/session.py", line 97, in wrapper
    return func(*args, session=session, **kwargs)
           ^^^^^^^^^^^^^^^^^^^^^^^^^^^^^^^^^^^^^^
  File "/home/airflow/.local/lib/python3.12/site-packages/airflow/models/taskinstance.py", line 3004, in _run_raw_task
    return _run_raw_task(
           ^^^^^^^^^^^^^^
  File "/home/airflow/.local/lib/python3.12/site-packages/airflow/models/taskinstance.py", line 273, in _run_raw_task
    TaskInstance._execute_task_with_callbacks(
  File "/home/airflow/.local/lib/python3.12/site-packages/airflow/models/taskinstance.py", line 3158, in _execute_task_with_callbacks
    result = self._execute_task(context, task_orig)
             ^^^^^^^^^^^^^^^^^^^^^^^^^^^^^^^^^^^^^^
  File "/home/airflow/.local/lib/python3.12/site-packages/airflow/models/taskinstance.py", line 3182, in _execute_task
    return _execute_task(self, context, task_orig)
           ^^^^^^^^^^^^^^^^^^^^^^^^^^^^^^^^^^^^^^^
  File "/home/airflow/.local/lib/python3.12/site-packages/airflow/models/taskinstance.py", line 767, in _execute_task
    result = _execute_callable(context=context, **execute_callable_kwargs)
             ^^^^^^^^^^^^^^^^^^^^^^^^^^^^^^^^^^^^^^^^^^^^^^^^^^^^^^^^^^^^^
  File "/home/airflow/.local/lib/python3.12/site-packages/airflow/models/taskinstance.py", line 733, in _execute_callable
    return ExecutionCallableRunner(
           ^^^^^^^^^^^^^^^^^^^^^^^^
  File "/home/airflow/.local/lib/python3.12/site-packages/airflow/utils/operator_helpers.py", line 252, in run
    return self.func(*args, **kwargs)
           ^^^^^^^^^^^^^^^^^^^^^^^^^^
  File "/home/airflow/.local/lib/python3.12/site-packages/airflow/models/baseoperator.py", line 406, in wrapper
    return func(self, *args, **kwargs)
           ^^^^^^^^^^^^^^^^^^^^^^^^^^^
  File "/home/airflow/.local/lib/python3.12/site-packages/airflow/operators/bash.py", line 249, in execute
    raise AirflowException(
airflow.exceptions.AirflowException: Bash command failed. The command returned a non-zero exit code 2.
[2025-05-05T23:39:40.910+0000] {local_task_job_runner.py:266} INFO - Task exited with return code 1
[2025-05-05T23:39:40.930+0000] {taskinstance.py:3900} INFO - 0 downstream tasks scheduled from follow-on schedule check
[2025-05-05T23:39:40.933+0000] {local_task_job_runner.py:245} INFO - ::endgroup::
