[2025-05-05T23:40:02.975+0000] {local_task_job_runner.py:123} INFO - ::group::Pre task execution logs
[2025-05-05T23:40:02.993+0000] {taskinstance.py:2612} INFO - Dependencies all met for dep_context=non-requeueable deps ti=<TaskInstance: dbt_sequential_run.dbt_run_marts scheduled__2025-05-04T02:00:00+00:00 [queued]>
[2025-05-05T23:40:03.000+0000] {taskinstance.py:2612} INFO - Dependencies all met for dep_context=requeueable deps ti=<TaskInstance: dbt_sequential_run.dbt_run_marts scheduled__2025-05-04T02:00:00+00:00 [queued]>
[2025-05-05T23:40:03.003+0000] {taskinstance.py:2865} INFO - Starting attempt 1 of 2
[2025-05-05T23:40:03.016+0000] {taskinstance.py:2888} INFO - Executing <Task(BashOperator): dbt_run_marts> on 2025-05-04 02:00:00+00:00
[2025-05-05T23:40:03.023+0000] {standard_task_runner.py:104} INFO - Running: ['***', 'tasks', 'run', 'dbt_sequential_run', 'dbt_run_marts', 'scheduled__2025-05-04T02:00:00+00:00', '--job-id', '16', '--raw', '--subdir', 'DAGS_FOLDER/dbt_run_dag.py', '--cfg-path', '/tmp/tmpiy9k5lor']
[2025-05-05T23:40:03.025+0000] {standard_task_runner.py:105} INFO - Job 16: Subtask dbt_run_marts
[2025-05-05T23:40:03.025+0000] {logging_mixin.py:190} WARNING - /home/***/.local/lib/python3.12/site-packages/***/task/task_runner/standard_task_runner.py:70 DeprecationWarning: This process (pid=488) is multi-threaded, use of fork() may lead to deadlocks in the child.
[2025-05-05T23:40:03.027+0000] {standard_task_runner.py:72} INFO - Started process 489 to run task
[2025-05-05T23:40:03.063+0000] {task_command.py:467} INFO - Running <TaskInstance: dbt_sequential_run.dbt_run_marts scheduled__2025-05-04T02:00:00+00:00 [running]> on host 5f6a5c55bc08
[2025-05-05T23:40:03.121+0000] {taskinstance.py:3131} INFO - Exporting env vars: AIRFLOW_CTX_DAG_OWNER='***' AIRFLOW_CTX_DAG_ID='dbt_sequential_run' AIRFLOW_CTX_TASK_ID='dbt_run_marts' AIRFLOW_CTX_EXECUTION_DATE='2025-05-04T02:00:00+00:00' AIRFLOW_CTX_TRY_NUMBER='1' AIRFLOW_CTX_DAG_RUN_ID='scheduled__2025-05-04T02:00:00+00:00'
[2025-05-05T23:40:03.122+0000] {taskinstance.py:731} INFO - ::endgroup::
[2025-05-05T23:40:03.137+0000] {subprocess.py:63} INFO - Tmp dir root location: /tmp
[2025-05-05T23:40:03.138+0000] {subprocess.py:75} INFO - Running command: ['/usr/bin/bash', '-c', '/home/***/.local/bin/dbt run --profiles-dir /opt/***/dbt --project-dir /opt/***/dbt --select marts']
[2025-05-05T23:40:03.147+0000] {subprocess.py:86} INFO - Output:
[2025-05-05T23:40:05.568+0000] {subprocess.py:93} INFO - [0m23:40:05  Running with dbt=1.8.7
[2025-05-05T23:40:06.753+0000] {subprocess.py:93} INFO - [0m23:40:06  Registered adapter: snowflake=1.8.1
[2025-05-05T23:40:07.793+0000] {subprocess.py:93} INFO - [0m23:40:07  Found 12 models, 10 data tests, 7 sources, 459 macros
[2025-05-05T23:40:07.796+0000] {subprocess.py:93} INFO - [0m23:40:07
[2025-05-05T23:40:09.045+0000] {subprocess.py:93} INFO - [0m23:40:09  Concurrency: 4 threads (target='dev')
[2025-05-05T23:40:09.045+0000] {subprocess.py:93} INFO - [0m23:40:09
[2025-05-05T23:40:09.058+0000] {subprocess.py:93} INFO - [0m23:40:09  1 of 5 START sql table model RAW_public.dim_address ............................ [RUN]
[2025-05-05T23:40:09.060+0000] {subprocess.py:93} INFO - [0m23:40:09  2 of 5 START sql table model RAW_public.dim_customer ........................... [RUN]
[2025-05-05T23:40:09.061+0000] {subprocess.py:93} INFO - [0m23:40:09  3 of 5 START sql incremental model RAW_public.fact_churn ....................... [RUN]
[2025-05-05T23:40:12.536+0000] {subprocess.py:93} INFO - [0m23:40:12  3 of 5 OK created sql incremental model RAW_public.fact_churn .................. [[32mSUCCESS 0[0m in 3.47s]
[2025-05-05T23:40:12.546+0000] {subprocess.py:93} INFO - [0m23:40:12  4 of 5 START sql table model RAW_public.churn_metrics .......................... [RUN]
[2025-05-05T23:40:13.258+0000] {subprocess.py:93} INFO - [0m23:40:13  4 of 5 ERROR creating sql table model RAW_public.churn_metrics ................. [[31mERROR[0m in 0.71s]
[2025-05-05T23:40:13.329+0000] {subprocess.py:93} INFO - [0m23:40:13  2 of 5 OK created sql table model RAW_public.dim_customer ...................... [[32mSUCCESS 1[0m in 4.26s]
[2025-05-05T23:40:14.044+0000] {subprocess.py:93} INFO - [0m23:40:14  1 of 5 OK created sql table model RAW_public.dim_address ....................... [[32mSUCCESS 1[0m in 4.98s]
[2025-05-05T23:40:14.050+0000] {subprocess.py:93} INFO - [0m23:40:14  5 of 5 START sql table model RAW_public.churn_map .............................. [RUN]
[2025-05-05T23:40:16.054+0000] {subprocess.py:93} INFO - [0m23:40:16  5 of 5 OK created sql table model RAW_public.churn_map ......................... [[32mSUCCESS 1[0m in 2.00s]
[2025-05-05T23:40:16.062+0000] {subprocess.py:93} INFO - [0m23:40:16
[2025-05-05T23:40:16.063+0000] {subprocess.py:93} INFO - [0m23:40:16  Finished running 1 incremental model, 4 table models in 0 hours 0 minutes and 8.27 seconds (8.27s).
[2025-05-05T23:40:16.162+0000] {subprocess.py:93} INFO - [0m23:40:16
[2025-05-05T23:40:16.163+0000] {subprocess.py:93} INFO - [0m23:40:16  [31mCompleted with 1 error and 0 warnings:[0m
[2025-05-05T23:40:16.164+0000] {subprocess.py:93} INFO - [0m23:40:16
[2025-05-05T23:40:16.166+0000] {subprocess.py:93} INFO - [0m23:40:16    Database Error in model churn_metrics (models/marts/churn_metrics.sql)
[2025-05-05T23:40:16.167+0000] {subprocess.py:93} INFO -   001003 (42000): SQL compilation error:
[2025-05-05T23:40:16.168+0000] {subprocess.py:93} INFO -   syntax error line 27 at position 0 unexpected 'by_tenure'.
[2025-05-05T23:40:16.168+0000] {subprocess.py:93} INFO -   syntax error line 29 at position 46 unexpected 'as'.
[2025-05-05T23:40:16.169+0000] {subprocess.py:93} INFO -   compiled code at target/run/customer_churn/models/marts/churn_metrics.sql
[2025-05-05T23:40:16.171+0000] {subprocess.py:93} INFO - [0m23:40:16
[2025-05-05T23:40:16.172+0000] {subprocess.py:93} INFO - [0m23:40:16  Done. PASS=4 WARN=0 ERROR=1 SKIP=0 TOTAL=5
[2025-05-05T23:40:17.006+0000] {subprocess.py:97} INFO - Command exited with return code 1
[2025-05-05T23:40:17.021+0000] {taskinstance.py:3310} ERROR - Task failed with exception
Traceback (most recent call last):
  File "/home/airflow/.local/lib/python3.12/site-packages/airflow/models/taskinstance.py", line 767, in _execute_task
    result = _execute_callable(context=context, **execute_callable_kwargs)
             ^^^^^^^^^^^^^^^^^^^^^^^^^^^^^^^^^^^^^^^^^^^^^^^^^^^^^^^^^^^^^
  File "/home/airflow/.local/lib/python3.12/site-packages/airflow/models/taskinstance.py", line 733, in _execute_callable
    return ExecutionCallableRunner(
           ^^^^^^^^^^^^^^^^^^^^^^^^
  File "/home/airflow/.local/lib/python3.12/site-packages/airflow/utils/operator_helpers.py", line 252, in run
    return self.func(*args, **kwargs)
           ^^^^^^^^^^^^^^^^^^^^^^^^^^
  File "/home/airflow/.local/lib/python3.12/site-packages/airflow/models/baseoperator.py", line 406, in wrapper
    return func(self, *args, **kwargs)
           ^^^^^^^^^^^^^^^^^^^^^^^^^^^
  File "/home/airflow/.local/lib/python3.12/site-packages/airflow/operators/bash.py", line 249, in execute
    raise AirflowException(
airflow.exceptions.AirflowException: Bash command failed. The command returned a non-zero exit code 1.
[2025-05-05T23:40:17.033+0000] {taskinstance.py:1225} INFO - Marking task as UP_FOR_RETRY. dag_id=dbt_sequential_run, task_id=dbt_run_marts, run_id=scheduled__2025-05-04T02:00:00+00:00, execution_date=20250504T020000, start_date=20250505T234002, end_date=20250505T234017
[2025-05-05T23:40:17.058+0000] {taskinstance.py:340} INFO - ::group::Post task execution logs
[2025-05-05T23:40:17.060+0000] {standard_task_runner.py:124} ERROR - Failed to execute job 16 for task dbt_run_marts (Bash command failed. The command returned a non-zero exit code 1.; 489)
Traceback (most recent call last):
  File "/home/airflow/.local/lib/python3.12/site-packages/airflow/task/task_runner/standard_task_runner.py", line 117, in _start_by_fork
    ret = args.func(args, dag=self.dag)
          ^^^^^^^^^^^^^^^^^^^^^^^^^^^^^
  File "/home/airflow/.local/lib/python3.12/site-packages/airflow/cli/cli_config.py", line 49, in command
    return func(*args, **kwargs)
           ^^^^^^^^^^^^^^^^^^^^^
  File "/home/airflow/.local/lib/python3.12/site-packages/airflow/utils/cli.py", line 115, in wrapper
    return f(*args, **kwargs)
           ^^^^^^^^^^^^^^^^^^
  File "/home/airflow/.local/lib/python3.12/site-packages/airflow/cli/commands/task_command.py", line 483, in task_run
    task_return_code = _run_task_by_selected_method(args, _dag, ti)
                       ^^^^^^^^^^^^^^^^^^^^^^^^^^^^^^^^^^^^^^^^^^^^
  File "/home/airflow/.local/lib/python3.12/site-packages/airflow/cli/commands/task_command.py", line 256, in _run_task_by_selected_method
    return _run_raw_task(args, ti)
           ^^^^^^^^^^^^^^^^^^^^^^^
  File "/home/airflow/.local/lib/python3.12/site-packages/airflow/cli/commands/task_command.py", line 341, in _run_raw_task
    return ti._run_raw_task(
           ^^^^^^^^^^^^^^^^^
  File "/home/airflow/.local/lib/python3.12/site-packages/airflow/utils/session.py", line 97, in wrapper
    return func(*args, session=session, **kwargs)
           ^^^^^^^^^^^^^^^^^^^^^^^^^^^^^^^^^^^^^^
  File "/home/airflow/.local/lib/python3.12/site-packages/airflow/models/taskinstance.py", line 3004, in _run_raw_task
    return _run_raw_task(
           ^^^^^^^^^^^^^^
  File "/home/airflow/.local/lib/python3.12/site-packages/airflow/models/taskinstance.py", line 273, in _run_raw_task
    TaskInstance._execute_task_with_callbacks(
  File "/home/airflow/.local/lib/python3.12/site-packages/airflow/models/taskinstance.py", line 3158, in _execute_task_with_callbacks
    result = self._execute_task(context, task_orig)
             ^^^^^^^^^^^^^^^^^^^^^^^^^^^^^^^^^^^^^^
  File "/home/airflow/.local/lib/python3.12/site-packages/airflow/models/taskinstance.py", line 3182, in _execute_task
    return _execute_task(self, context, task_orig)
           ^^^^^^^^^^^^^^^^^^^^^^^^^^^^^^^^^^^^^^^
  File "/home/airflow/.local/lib/python3.12/site-packages/airflow/models/taskinstance.py", line 767, in _execute_task
    result = _execute_callable(context=context, **execute_callable_kwargs)
             ^^^^^^^^^^^^^^^^^^^^^^^^^^^^^^^^^^^^^^^^^^^^^^^^^^^^^^^^^^^^^
  File "/home/airflow/.local/lib/python3.12/site-packages/airflow/models/taskinstance.py", line 733, in _execute_callable
    return ExecutionCallableRunner(
           ^^^^^^^^^^^^^^^^^^^^^^^^
  File "/home/airflow/.local/lib/python3.12/site-packages/airflow/utils/operator_helpers.py", line 252, in run
    return self.func(*args, **kwargs)
           ^^^^^^^^^^^^^^^^^^^^^^^^^^
  File "/home/airflow/.local/lib/python3.12/site-packages/airflow/models/baseoperator.py", line 406, in wrapper
    return func(self, *args, **kwargs)
           ^^^^^^^^^^^^^^^^^^^^^^^^^^^
  File "/home/airflow/.local/lib/python3.12/site-packages/airflow/operators/bash.py", line 249, in execute
    raise AirflowException(
airflow.exceptions.AirflowException: Bash command failed. The command returned a non-zero exit code 1.
[2025-05-05T23:40:17.074+0000] {local_task_job_runner.py:266} INFO - Task exited with return code 1
[2025-05-05T23:40:17.102+0000] {taskinstance.py:3900} INFO - 0 downstream tasks scheduled from follow-on schedule check
[2025-05-05T23:40:17.105+0000] {local_task_job_runner.py:245} INFO - ::endgroup::
[2025-05-05T23:49:22.700+0000] {local_task_job_runner.py:123} INFO - ::group::Pre task execution logs
[2025-05-05T23:49:22.720+0000] {taskinstance.py:2612} INFO - Dependencies all met for dep_context=non-requeueable deps ti=<TaskInstance: dbt_sequential_run.dbt_run_marts scheduled__2025-05-04T02:00:00+00:00 [queued]>
[2025-05-05T23:49:22.730+0000] {taskinstance.py:2612} INFO - Dependencies all met for dep_context=requeueable deps ti=<TaskInstance: dbt_sequential_run.dbt_run_marts scheduled__2025-05-04T02:00:00+00:00 [queued]>
[2025-05-05T23:49:22.736+0000] {taskinstance.py:2865} INFO - Starting attempt 1 of 2
[2025-05-05T23:49:22.750+0000] {taskinstance.py:2888} INFO - Executing <Task(BashOperator): dbt_run_marts> on 2025-05-04 02:00:00+00:00
[2025-05-05T23:49:22.757+0000] {standard_task_runner.py:104} INFO - Running: ['***', 'tasks', 'run', 'dbt_sequential_run', 'dbt_run_marts', 'scheduled__2025-05-04T02:00:00+00:00', '--job-id', '33', '--raw', '--subdir', 'DAGS_FOLDER/dbt_run_dag.py', '--cfg-path', '/tmp/tmpe3twpc5y']
[2025-05-05T23:49:22.760+0000] {standard_task_runner.py:105} INFO - Job 33: Subtask dbt_run_marts
[2025-05-05T23:49:22.761+0000] {logging_mixin.py:190} WARNING - /home/***/.local/lib/python3.12/site-packages/***/task/task_runner/standard_task_runner.py:70 DeprecationWarning: This process (pid=1413) is multi-threaded, use of fork() may lead to deadlocks in the child.
[2025-05-05T23:49:22.762+0000] {standard_task_runner.py:72} INFO - Started process 1415 to run task
[2025-05-05T23:49:22.808+0000] {task_command.py:467} INFO - Running <TaskInstance: dbt_sequential_run.dbt_run_marts scheduled__2025-05-04T02:00:00+00:00 [running]> on host 5f6a5c55bc08
[2025-05-05T23:49:22.892+0000] {taskinstance.py:3131} INFO - Exporting env vars: AIRFLOW_CTX_DAG_OWNER='***' AIRFLOW_CTX_DAG_ID='dbt_sequential_run' AIRFLOW_CTX_TASK_ID='dbt_run_marts' AIRFLOW_CTX_EXECUTION_DATE='2025-05-04T02:00:00+00:00' AIRFLOW_CTX_TRY_NUMBER='1' AIRFLOW_CTX_DAG_RUN_ID='scheduled__2025-05-04T02:00:00+00:00'
[2025-05-05T23:49:22.893+0000] {taskinstance.py:731} INFO - ::endgroup::
[2025-05-05T23:49:22.910+0000] {subprocess.py:63} INFO - Tmp dir root location: /tmp
[2025-05-05T23:49:22.911+0000] {subprocess.py:75} INFO - Running command: ['/usr/bin/bash', '-c', '/home/***/.local/bin/dbt run --profiles-dir /opt/***/dbt --project-dir /opt/***/dbt --select marts']
[2025-05-05T23:49:22.919+0000] {subprocess.py:86} INFO - Output:
[2025-05-05T23:49:25.459+0000] {subprocess.py:93} INFO - [0m23:49:25  Running with dbt=1.8.7
[2025-05-05T23:49:27.028+0000] {subprocess.py:93} INFO - [0m23:49:27  Registered adapter: snowflake=1.8.1
[2025-05-05T23:49:28.145+0000] {subprocess.py:93} INFO - [0m23:49:28  Found 12 models, 10 data tests, 7 sources, 459 macros
[2025-05-05T23:49:28.148+0000] {subprocess.py:93} INFO - [0m23:49:28
[2025-05-05T23:49:29.630+0000] {subprocess.py:93} INFO - [0m23:49:29  Concurrency: 4 threads (target='dev')
[2025-05-05T23:49:29.631+0000] {subprocess.py:93} INFO - [0m23:49:29
[2025-05-05T23:49:29.658+0000] {subprocess.py:93} INFO - [0m23:49:29  1 of 5 START sql table model RAW_public.dim_address ............................ [RUN]
[2025-05-05T23:49:29.661+0000] {subprocess.py:93} INFO - [0m23:49:29  2 of 5 START sql table model RAW_public.dim_customer ........................... [RUN]
[2025-05-05T23:49:29.705+0000] {subprocess.py:93} INFO - [0m23:49:29  3 of 5 START sql incremental model RAW_public.fact_churn ....................... [RUN]
[2025-05-05T23:49:34.586+0000] {subprocess.py:93} INFO - [0m23:49:34  2 of 5 OK created sql table model RAW_public.dim_customer ...................... [[32mSUCCESS 1[0m in 4.82s]
[2025-05-05T23:49:34.890+0000] {subprocess.py:93} INFO - [0m23:49:34  3 of 5 OK created sql incremental model RAW_public.fact_churn .................. [[32mSUCCESS 0[0m in 5.11s]
[2025-05-05T23:49:34.933+0000] {subprocess.py:93} INFO - [0m23:49:34  4 of 5 START sql table model RAW_public.churn_metrics .......................... [RUN]
[2025-05-05T23:49:35.188+0000] {subprocess.py:93} INFO - [0m23:49:35  1 of 5 OK created sql table model RAW_public.dim_address ....................... [[32mSUCCESS 1[0m in 5.47s]
[2025-05-05T23:49:35.196+0000] {subprocess.py:93} INFO - [0m23:49:35  5 of 5 START sql table model RAW_public.churn_map .............................. [RUN]
[2025-05-05T23:49:35.560+0000] {subprocess.py:93} INFO - [0m23:49:35  4 of 5 ERROR creating sql table model RAW_public.churn_metrics ................. [[31mERROR[0m in 0.62s]
[2025-05-05T23:49:37.726+0000] {subprocess.py:93} INFO - [0m23:49:37  5 of 5 OK created sql table model RAW_public.churn_map ......................... [[32mSUCCESS 1[0m in 2.53s]
[2025-05-05T23:49:37.735+0000] {subprocess.py:93} INFO - [0m23:49:37
[2025-05-05T23:49:37.736+0000] {subprocess.py:93} INFO - [0m23:49:37  Finished running 4 table models, 1 incremental model in 0 hours 0 minutes and 9.59 seconds (9.59s).
[2025-05-05T23:49:37.842+0000] {subprocess.py:93} INFO - [0m23:49:37
[2025-05-05T23:49:37.843+0000] {subprocess.py:93} INFO - [0m23:49:37  [31mCompleted with 1 error and 0 warnings:[0m
[2025-05-05T23:49:37.844+0000] {subprocess.py:93} INFO - [0m23:49:37
[2025-05-05T23:49:37.845+0000] {subprocess.py:93} INFO - [0m23:49:37    Database Error in model churn_metrics (models/marts/churn_metrics.sql)
[2025-05-05T23:49:37.846+0000] {subprocess.py:93} INFO -   001003 (42000): SQL compilation error:
[2025-05-05T23:49:37.847+0000] {subprocess.py:93} INFO -   syntax error line 40 at position 15 unexpected ';'.
[2025-05-05T23:49:37.847+0000] {subprocess.py:93} INFO -   compiled code at target/run/customer_churn/models/marts/churn_metrics.sql
[2025-05-05T23:49:37.848+0000] {subprocess.py:93} INFO - [0m23:49:37
[2025-05-05T23:49:37.849+0000] {subprocess.py:93} INFO - [0m23:49:37  Done. PASS=4 WARN=0 ERROR=1 SKIP=0 TOTAL=5
[2025-05-05T23:49:38.583+0000] {subprocess.py:97} INFO - Command exited with return code 1
[2025-05-05T23:49:38.597+0000] {taskinstance.py:3310} ERROR - Task failed with exception
Traceback (most recent call last):
  File "/home/airflow/.local/lib/python3.12/site-packages/airflow/models/taskinstance.py", line 767, in _execute_task
    result = _execute_callable(context=context, **execute_callable_kwargs)
             ^^^^^^^^^^^^^^^^^^^^^^^^^^^^^^^^^^^^^^^^^^^^^^^^^^^^^^^^^^^^^
  File "/home/airflow/.local/lib/python3.12/site-packages/airflow/models/taskinstance.py", line 733, in _execute_callable
    return ExecutionCallableRunner(
           ^^^^^^^^^^^^^^^^^^^^^^^^
  File "/home/airflow/.local/lib/python3.12/site-packages/airflow/utils/operator_helpers.py", line 252, in run
    return self.func(*args, **kwargs)
           ^^^^^^^^^^^^^^^^^^^^^^^^^^
  File "/home/airflow/.local/lib/python3.12/site-packages/airflow/models/baseoperator.py", line 406, in wrapper
    return func(self, *args, **kwargs)
           ^^^^^^^^^^^^^^^^^^^^^^^^^^^
  File "/home/airflow/.local/lib/python3.12/site-packages/airflow/operators/bash.py", line 249, in execute
    raise AirflowException(
airflow.exceptions.AirflowException: Bash command failed. The command returned a non-zero exit code 1.
[2025-05-05T23:49:38.605+0000] {taskinstance.py:1225} INFO - Marking task as UP_FOR_RETRY. dag_id=dbt_sequential_run, task_id=dbt_run_marts, run_id=scheduled__2025-05-04T02:00:00+00:00, execution_date=20250504T020000, start_date=20250505T234922, end_date=20250505T234938
[2025-05-05T23:49:38.621+0000] {taskinstance.py:340} INFO - ::group::Post task execution logs
[2025-05-05T23:49:38.622+0000] {standard_task_runner.py:124} ERROR - Failed to execute job 33 for task dbt_run_marts (Bash command failed. The command returned a non-zero exit code 1.; 1415)
Traceback (most recent call last):
  File "/home/airflow/.local/lib/python3.12/site-packages/airflow/task/task_runner/standard_task_runner.py", line 117, in _start_by_fork
    ret = args.func(args, dag=self.dag)
          ^^^^^^^^^^^^^^^^^^^^^^^^^^^^^
  File "/home/airflow/.local/lib/python3.12/site-packages/airflow/cli/cli_config.py", line 49, in command
    return func(*args, **kwargs)
           ^^^^^^^^^^^^^^^^^^^^^
  File "/home/airflow/.local/lib/python3.12/site-packages/airflow/utils/cli.py", line 115, in wrapper
    return f(*args, **kwargs)
           ^^^^^^^^^^^^^^^^^^
  File "/home/airflow/.local/lib/python3.12/site-packages/airflow/cli/commands/task_command.py", line 483, in task_run
    task_return_code = _run_task_by_selected_method(args, _dag, ti)
                       ^^^^^^^^^^^^^^^^^^^^^^^^^^^^^^^^^^^^^^^^^^^^
  File "/home/airflow/.local/lib/python3.12/site-packages/airflow/cli/commands/task_command.py", line 256, in _run_task_by_selected_method
    return _run_raw_task(args, ti)
           ^^^^^^^^^^^^^^^^^^^^^^^
  File "/home/airflow/.local/lib/python3.12/site-packages/airflow/cli/commands/task_command.py", line 341, in _run_raw_task
    return ti._run_raw_task(
           ^^^^^^^^^^^^^^^^^
  File "/home/airflow/.local/lib/python3.12/site-packages/airflow/utils/session.py", line 97, in wrapper
    return func(*args, session=session, **kwargs)
           ^^^^^^^^^^^^^^^^^^^^^^^^^^^^^^^^^^^^^^
  File "/home/airflow/.local/lib/python3.12/site-packages/airflow/models/taskinstance.py", line 3004, in _run_raw_task
    return _run_raw_task(
           ^^^^^^^^^^^^^^
  File "/home/airflow/.local/lib/python3.12/site-packages/airflow/models/taskinstance.py", line 273, in _run_raw_task
    TaskInstance._execute_task_with_callbacks(
  File "/home/airflow/.local/lib/python3.12/site-packages/airflow/models/taskinstance.py", line 3158, in _execute_task_with_callbacks
    result = self._execute_task(context, task_orig)
             ^^^^^^^^^^^^^^^^^^^^^^^^^^^^^^^^^^^^^^
  File "/home/airflow/.local/lib/python3.12/site-packages/airflow/models/taskinstance.py", line 3182, in _execute_task
    return _execute_task(self, context, task_orig)
           ^^^^^^^^^^^^^^^^^^^^^^^^^^^^^^^^^^^^^^^
  File "/home/airflow/.local/lib/python3.12/site-packages/airflow/models/taskinstance.py", line 767, in _execute_task
    result = _execute_callable(context=context, **execute_callable_kwargs)
             ^^^^^^^^^^^^^^^^^^^^^^^^^^^^^^^^^^^^^^^^^^^^^^^^^^^^^^^^^^^^^
  File "/home/airflow/.local/lib/python3.12/site-packages/airflow/models/taskinstance.py", line 733, in _execute_callable
    return ExecutionCallableRunner(
           ^^^^^^^^^^^^^^^^^^^^^^^^
  File "/home/airflow/.local/lib/python3.12/site-packages/airflow/utils/operator_helpers.py", line 252, in run
    return self.func(*args, **kwargs)
           ^^^^^^^^^^^^^^^^^^^^^^^^^^
  File "/home/airflow/.local/lib/python3.12/site-packages/airflow/models/baseoperator.py", line 406, in wrapper
    return func(self, *args, **kwargs)
           ^^^^^^^^^^^^^^^^^^^^^^^^^^^
  File "/home/airflow/.local/lib/python3.12/site-packages/airflow/operators/bash.py", line 249, in execute
    raise AirflowException(
airflow.exceptions.AirflowException: Bash command failed. The command returned a non-zero exit code 1.
[2025-05-05T23:49:38.642+0000] {local_task_job_runner.py:266} INFO - Task exited with return code 1
[2025-05-05T23:49:38.667+0000] {taskinstance.py:3900} INFO - 0 downstream tasks scheduled from follow-on schedule check
[2025-05-05T23:49:38.670+0000] {local_task_job_runner.py:245} INFO - ::endgroup::
[2025-05-05T23:54:20.977+0000] {local_task_job_runner.py:123} INFO - ::group::Pre task execution logs
[2025-05-05T23:54:20.992+0000] {taskinstance.py:2612} INFO - Dependencies all met for dep_context=non-requeueable deps ti=<TaskInstance: dbt_sequential_run.dbt_run_marts scheduled__2025-05-04T02:00:00+00:00 [queued]>
[2025-05-05T23:54:21.000+0000] {taskinstance.py:2612} INFO - Dependencies all met for dep_context=requeueable deps ti=<TaskInstance: dbt_sequential_run.dbt_run_marts scheduled__2025-05-04T02:00:00+00:00 [queued]>
[2025-05-05T23:54:21.001+0000] {taskinstance.py:2865} INFO - Starting attempt 1 of 2
[2025-05-05T23:54:21.014+0000] {taskinstance.py:2888} INFO - Executing <Task(BashOperator): dbt_run_marts> on 2025-05-04 02:00:00+00:00
[2025-05-05T23:54:21.021+0000] {standard_task_runner.py:104} INFO - Running: ['***', 'tasks', 'run', 'dbt_sequential_run', 'dbt_run_marts', 'scheduled__2025-05-04T02:00:00+00:00', '--job-id', '39', '--raw', '--subdir', 'DAGS_FOLDER/dbt_run_dag.py', '--cfg-path', '/tmp/tmpvvawwcc7']
[2025-05-05T23:54:21.024+0000] {standard_task_runner.py:105} INFO - Job 39: Subtask dbt_run_marts
[2025-05-05T23:54:21.025+0000] {logging_mixin.py:190} WARNING - /home/***/.local/lib/python3.12/site-packages/***/task/task_runner/standard_task_runner.py:70 DeprecationWarning: This process (pid=1747) is multi-threaded, use of fork() may lead to deadlocks in the child.
[2025-05-05T23:54:21.026+0000] {standard_task_runner.py:72} INFO - Started process 1748 to run task
[2025-05-05T23:54:21.067+0000] {task_command.py:467} INFO - Running <TaskInstance: dbt_sequential_run.dbt_run_marts scheduled__2025-05-04T02:00:00+00:00 [running]> on host 5f6a5c55bc08
[2025-05-05T23:54:21.138+0000] {taskinstance.py:3131} INFO - Exporting env vars: AIRFLOW_CTX_DAG_OWNER='***' AIRFLOW_CTX_DAG_ID='dbt_sequential_run' AIRFLOW_CTX_TASK_ID='dbt_run_marts' AIRFLOW_CTX_EXECUTION_DATE='2025-05-04T02:00:00+00:00' AIRFLOW_CTX_TRY_NUMBER='1' AIRFLOW_CTX_DAG_RUN_ID='scheduled__2025-05-04T02:00:00+00:00'
[2025-05-05T23:54:21.139+0000] {taskinstance.py:731} INFO - ::endgroup::
[2025-05-05T23:54:21.161+0000] {subprocess.py:63} INFO - Tmp dir root location: /tmp
[2025-05-05T23:54:21.162+0000] {subprocess.py:75} INFO - Running command: ['/usr/bin/bash', '-c', '/home/***/.local/bin/dbt run --profiles-dir /opt/***/dbt --project-dir /opt/***/dbt --select marts']
[2025-05-05T23:54:21.172+0000] {subprocess.py:86} INFO - Output:
[2025-05-05T23:54:23.665+0000] {subprocess.py:93} INFO - [0m23:54:23  Running with dbt=1.8.7
[2025-05-05T23:54:24.898+0000] {subprocess.py:93} INFO - [0m23:54:24  Registered adapter: snowflake=1.8.1
[2025-05-05T23:54:25.844+0000] {subprocess.py:93} INFO - [0m23:54:25  Found 12 models, 10 data tests, 7 sources, 459 macros
[2025-05-05T23:54:25.848+0000] {subprocess.py:93} INFO - [0m23:54:25
[2025-05-05T23:54:28.536+0000] {subprocess.py:93} INFO - [0m23:54:28  Concurrency: 4 threads (target='dev')
[2025-05-05T23:54:28.537+0000] {subprocess.py:93} INFO - [0m23:54:28
[2025-05-05T23:54:28.550+0000] {subprocess.py:93} INFO - [0m23:54:28  1 of 5 START sql table model RAW_public.dim_address ............................ [RUN]
[2025-05-05T23:54:28.551+0000] {subprocess.py:93} INFO - [0m23:54:28  2 of 5 START sql table model RAW_public.dim_customer ........................... [RUN]
[2025-05-05T23:54:28.552+0000] {subprocess.py:93} INFO - [0m23:54:28  3 of 5 START sql incremental model RAW_public.fact_churn ....................... [RUN]
[2025-05-05T23:54:32.550+0000] {subprocess.py:93} INFO - [0m23:54:32  2 of 5 OK created sql table model RAW_public.dim_customer ...................... [[32mSUCCESS 1[0m in 3.97s]
[2025-05-05T23:54:33.089+0000] {subprocess.py:93} INFO - [0m23:54:33  3 of 5 OK created sql incremental model RAW_public.fact_churn .................. [[32mSUCCESS 0[0m in 4.53s]
[2025-05-05T23:54:33.094+0000] {subprocess.py:93} INFO - [0m23:54:33  4 of 5 START sql table model RAW_public.churn_metrics .......................... [RUN]
[2025-05-05T23:54:33.628+0000] {subprocess.py:93} INFO - [0m23:54:33  1 of 5 OK created sql table model RAW_public.dim_address ....................... [[32mSUCCESS 1[0m in 5.06s]
[2025-05-05T23:54:33.641+0000] {subprocess.py:93} INFO - [0m23:54:33  5 of 5 START sql table model RAW_public.churn_map .............................. [RUN]
[2025-05-05T23:54:34.451+0000] {subprocess.py:93} INFO - [0m23:54:34  4 of 5 ERROR creating sql table model RAW_public.churn_metrics ................. [[31mERROR[0m in 1.35s]
[2025-05-05T23:54:35.303+0000] {subprocess.py:93} INFO - [0m23:54:35  5 of 5 OK created sql table model RAW_public.churn_map ......................... [[32mSUCCESS 1[0m in 1.66s]
[2025-05-05T23:54:35.329+0000] {subprocess.py:93} INFO - [0m23:54:35
[2025-05-05T23:54:35.330+0000] {subprocess.py:93} INFO - [0m23:54:35  Finished running 4 table models, 1 incremental model in 0 hours 0 minutes and 9.48 seconds (9.48s).
[2025-05-05T23:54:35.662+0000] {subprocess.py:93} INFO - [0m23:54:35
[2025-05-05T23:54:35.666+0000] {subprocess.py:93} INFO - [0m23:54:35  [31mCompleted with 1 error and 0 warnings:[0m
[2025-05-05T23:54:35.668+0000] {subprocess.py:93} INFO - [0m23:54:35
[2025-05-05T23:54:35.670+0000] {subprocess.py:93} INFO - [0m23:54:35    Database Error in model churn_metrics (models/marts/churn_metrics.sql)
[2025-05-05T23:54:35.671+0000] {subprocess.py:93} INFO -   000904 (42000): SQL compilation error: error line 22 at position 6
[2025-05-05T23:54:35.672+0000] {subprocess.py:93} INFO -   invalid identifier 'AGE_GROUP'
[2025-05-05T23:54:35.673+0000] {subprocess.py:93} INFO -   compiled code at target/run/customer_churn/models/marts/churn_metrics.sql
[2025-05-05T23:54:35.674+0000] {subprocess.py:93} INFO - [0m23:54:35
[2025-05-05T23:54:35.675+0000] {subprocess.py:93} INFO - [0m23:54:35  Done. PASS=4 WARN=0 ERROR=1 SKIP=0 TOTAL=5
[2025-05-05T23:54:36.470+0000] {subprocess.py:97} INFO - Command exited with return code 1
[2025-05-05T23:54:36.477+0000] {taskinstance.py:3310} ERROR - Task failed with exception
Traceback (most recent call last):
  File "/home/airflow/.local/lib/python3.12/site-packages/airflow/models/taskinstance.py", line 767, in _execute_task
    result = _execute_callable(context=context, **execute_callable_kwargs)
             ^^^^^^^^^^^^^^^^^^^^^^^^^^^^^^^^^^^^^^^^^^^^^^^^^^^^^^^^^^^^^
  File "/home/airflow/.local/lib/python3.12/site-packages/airflow/models/taskinstance.py", line 733, in _execute_callable
    return ExecutionCallableRunner(
           ^^^^^^^^^^^^^^^^^^^^^^^^
  File "/home/airflow/.local/lib/python3.12/site-packages/airflow/utils/operator_helpers.py", line 252, in run
    return self.func(*args, **kwargs)
           ^^^^^^^^^^^^^^^^^^^^^^^^^^
  File "/home/airflow/.local/lib/python3.12/site-packages/airflow/models/baseoperator.py", line 406, in wrapper
    return func(self, *args, **kwargs)
           ^^^^^^^^^^^^^^^^^^^^^^^^^^^
  File "/home/airflow/.local/lib/python3.12/site-packages/airflow/operators/bash.py", line 249, in execute
    raise AirflowException(
airflow.exceptions.AirflowException: Bash command failed. The command returned a non-zero exit code 1.
[2025-05-05T23:54:36.486+0000] {taskinstance.py:1225} INFO - Marking task as UP_FOR_RETRY. dag_id=dbt_sequential_run, task_id=dbt_run_marts, run_id=scheduled__2025-05-04T02:00:00+00:00, execution_date=20250504T020000, start_date=20250505T235420, end_date=20250505T235436
[2025-05-05T23:54:36.503+0000] {taskinstance.py:340} INFO - ::group::Post task execution logs
[2025-05-05T23:54:36.504+0000] {standard_task_runner.py:124} ERROR - Failed to execute job 39 for task dbt_run_marts (Bash command failed. The command returned a non-zero exit code 1.; 1748)
Traceback (most recent call last):
  File "/home/airflow/.local/lib/python3.12/site-packages/airflow/task/task_runner/standard_task_runner.py", line 117, in _start_by_fork
    ret = args.func(args, dag=self.dag)
          ^^^^^^^^^^^^^^^^^^^^^^^^^^^^^
  File "/home/airflow/.local/lib/python3.12/site-packages/airflow/cli/cli_config.py", line 49, in command
    return func(*args, **kwargs)
           ^^^^^^^^^^^^^^^^^^^^^
  File "/home/airflow/.local/lib/python3.12/site-packages/airflow/utils/cli.py", line 115, in wrapper
    return f(*args, **kwargs)
           ^^^^^^^^^^^^^^^^^^
  File "/home/airflow/.local/lib/python3.12/site-packages/airflow/cli/commands/task_command.py", line 483, in task_run
    task_return_code = _run_task_by_selected_method(args, _dag, ti)
                       ^^^^^^^^^^^^^^^^^^^^^^^^^^^^^^^^^^^^^^^^^^^^
  File "/home/airflow/.local/lib/python3.12/site-packages/airflow/cli/commands/task_command.py", line 256, in _run_task_by_selected_method
    return _run_raw_task(args, ti)
           ^^^^^^^^^^^^^^^^^^^^^^^
  File "/home/airflow/.local/lib/python3.12/site-packages/airflow/cli/commands/task_command.py", line 341, in _run_raw_task
    return ti._run_raw_task(
           ^^^^^^^^^^^^^^^^^
  File "/home/airflow/.local/lib/python3.12/site-packages/airflow/utils/session.py", line 97, in wrapper
    return func(*args, session=session, **kwargs)
           ^^^^^^^^^^^^^^^^^^^^^^^^^^^^^^^^^^^^^^
  File "/home/airflow/.local/lib/python3.12/site-packages/airflow/models/taskinstance.py", line 3004, in _run_raw_task
    return _run_raw_task(
           ^^^^^^^^^^^^^^
  File "/home/airflow/.local/lib/python3.12/site-packages/airflow/models/taskinstance.py", line 273, in _run_raw_task
    TaskInstance._execute_task_with_callbacks(
  File "/home/airflow/.local/lib/python3.12/site-packages/airflow/models/taskinstance.py", line 3158, in _execute_task_with_callbacks
    result = self._execute_task(context, task_orig)
             ^^^^^^^^^^^^^^^^^^^^^^^^^^^^^^^^^^^^^^
  File "/home/airflow/.local/lib/python3.12/site-packages/airflow/models/taskinstance.py", line 3182, in _execute_task
    return _execute_task(self, context, task_orig)
           ^^^^^^^^^^^^^^^^^^^^^^^^^^^^^^^^^^^^^^^
  File "/home/airflow/.local/lib/python3.12/site-packages/airflow/models/taskinstance.py", line 767, in _execute_task
    result = _execute_callable(context=context, **execute_callable_kwargs)
             ^^^^^^^^^^^^^^^^^^^^^^^^^^^^^^^^^^^^^^^^^^^^^^^^^^^^^^^^^^^^^
  File "/home/airflow/.local/lib/python3.12/site-packages/airflow/models/taskinstance.py", line 733, in _execute_callable
    return ExecutionCallableRunner(
           ^^^^^^^^^^^^^^^^^^^^^^^^
  File "/home/airflow/.local/lib/python3.12/site-packages/airflow/utils/operator_helpers.py", line 252, in run
    return self.func(*args, **kwargs)
           ^^^^^^^^^^^^^^^^^^^^^^^^^^
  File "/home/airflow/.local/lib/python3.12/site-packages/airflow/models/baseoperator.py", line 406, in wrapper
    return func(self, *args, **kwargs)
           ^^^^^^^^^^^^^^^^^^^^^^^^^^^
  File "/home/airflow/.local/lib/python3.12/site-packages/airflow/operators/bash.py", line 249, in execute
    raise AirflowException(
airflow.exceptions.AirflowException: Bash command failed. The command returned a non-zero exit code 1.
[2025-05-05T23:54:36.512+0000] {local_task_job_runner.py:266} INFO - Task exited with return code 1
[2025-05-05T23:54:36.527+0000] {taskinstance.py:3900} INFO - 0 downstream tasks scheduled from follow-on schedule check
[2025-05-05T23:54:36.528+0000] {local_task_job_runner.py:245} INFO - ::endgroup::
